Workbook

Sheet NOV
A1: Team Budget Nov-2024 Collection
A2: Serial No. | B2: Member Name | C2: Received Date | D2: Amount | H2: Serial No. | I2: Date | J2: Nov- Expenses | K2: Amount | L2: By Whom
A3: 1 | B3: Abhay Sir | C3: 45618 | D3: 2000 | H3: 1 | I3: 45611 | J3: Refreshment | K3: 200 | L3: Deepak Sir
A4: 2 | B4: Amit Singh (Bade) | C4: 45619 | D4: 2000 | H4: 2 | I4: 45617 | J4: Cricket Kit | K4: 19700 | L4: Shivam & Deepak Sir
A5: 3 | B5: Amit Singh (Chhotu) | C5: 45617 | D5: 2000 | H5: 3 | I5: 45618 | J5: Wicket Keeping Gloves | K5: 1700 | L5: Shivam
A6: 4 | B6: Atul Shukla | H6: 4 | I6: 45618 | J6: SS Cricket Bat | K6: 2200 | L6: Amit Singh (Bade)
A7: 5 | B7: Deepak Sir | C7: 45617 | D7: 2000 | H7: 5 | I7: 45619 | J7: Refreshment | K7: 150 | L7: Deepak Sir
A8: 6 | B8: Gaurav Bhai | C8: 45618 | D8: 2000 | H8: 6 | I8: 45620 | J8: Refreshment | K8: 70 | L8: Hasan Sir
A9: 7 | B9: Hassan | C9: 45617 | D9: 2000 | H9: 7
A10: 8 | B10: Kakad Sir | C10: 45618 | D10: 2000 | K10: =SUM(K3:K9) -> 24020
A11: 9 | B11: Shalu | C11: 45618 | D11: 2000
A12: 10 | B12: Shivam | C12: 45617 | D12: 2000
A13: 11 | B13: Sunil | C13: 45618 | D13: 2000
A14: 12 | B14: Zikrul | C14: 45617 | D14: 2000
D15: =SUM(D3:D14) -> 22000
B18: Nov Collection | C18: =D15 -> 22000
B19: Prev Balance | C19: 0
B20: Total Collection Amount | C20: =D15 -> 22000
B21: Total Expenses Amount | C21: =K10 -> 24020
B22: Balance Amount | C22: =SUM(C19+C20-C21) -> -2020

Sheet Registration Fee
A1: Sr No | B1: Name | C1: Amount | D1: Date
A2: 1 | B2: Amit Singh (Chhotu) | C2: 2000 | D2: 45617
A3: 2 | B3: Deepak Sir | C3: 2000 | D3: 45617
A4: 3 | B4: Hassan | C4: 2000 | D4: 45617
A5: 4 | B5: Shivam | C5: 2000 | D5: 45617
A6: 5 | B6: Zikrul | C6: 2000 | D6: 45617
A7: 6 | B7: Abhay Sir | C7: 2000 | D7: 45618
A8: 7 | B8: Gaurav Bhai | C8: 2000 | D8: 45618
A9: 8 | B9: Kakad Sir | C9: 2000 | D9: 45618
A10: 9 | B10: Shalu | C10: 2000 | D10: 45618
A11: 10 | B11: Sunil | C11: 2000 | D11: 45618
A12: 11 | B12: Amit Singh (Bade) | C12: 2000 | D12: 45619
A13: 12 | B13: Sunil Verma Sir | C13: 2000 | D13: 45629
... A53: 52 | B53: Ashish Singh | C53: 2500 | D53: 46063
A57: Total | C57: =SUM(C2:C53) -> 101500

Sheet DEC
A1: Team Budget Dec-2024 Collection
A2: Serial No. | B2: Member Name | C2: Received Date | D2: Entry Fee paid | E2: Subs Fee paid | G2: Serial No. | H2: Date | I2: Dec- Expenses | J2: Amount | K2: By Whom
A3: 1 | B3: Abhay Sir | C3: 45650 | E3: 500 | G3: 1 | H3: 45627 | I3: Refreshment | J3: 200 | K3: Shivam & Zikrul
A4: 2 | B4: Amit Singh (Bade) | C4: 45636 | E4: 500 | G4: 2 | H4: 45629 | I4: Ground Booked | J4: 4000 | K4: Shivam
A5: 3 | B5: Amit Singh (Chhotu) | E5: 0 | G5: 3 | H5: 45629 | I5: Extra kit & Bat Repair | J5: 6300 | K5: Shivam & Zikrul
A6: 4 | B6: Atul Shukla | C6: 45630 | D6: 2000 | E6: 500 | G6: 4 | H6: 45629 | I6: Bat Knocking | J6: 600 | K6: Zikrul
A7: 5 | B7: Deepak Sir | C7: 45636 | E7: 500 | G7: 5 | H7: 45633 | I7: Refreshment & First Aid | J7: 170 | K7: Hasan & Shivam
A8: 6 | B8: Gaurav Bhai | C8: 45637 | E8: 500 | G8: 6 | H8: 45648 | I8: Refreshment | J8: 130 | K8: Amit Singh (Bade)
A9: 7 | B9: Hassan | C9: 45635 | E9: 500 | G9: 7 | H9: 45651 | I9: Ground Booking | J9: 3550 | K9: Shivam & Gaurav Bhai
A10: 8 | B10: Kakad Sir | C10: 45639 | E10: 500 | G10: 8 | H10: 45651 | I10: 6 Balls | J10: 2000 | K10: Shalu
A11: 9 | B11: Shalu | E11: 500 | G11: 9 | H11: 45659 | I11: Advance for Gosaiganj Ground | J11: 500
A12: 10 | B12: Shivam | C12: 45599 | E12: 500
A13: 11 | B13: Sunil | E13: 500
A14: 12 | B14: Zikrul | C14: 45599 | E14: 500
A15: 13 | B15: Madhu Sir | C15: 45649 | D15: 2000 | E15: 500 | J15: =SUM(J3:J14) -> 17450
A16: 14 | B16: Sunil Verma Sir | C16: 45629 | D16: 2000 | E16: 500
A17: 15 | B17: Akash Bhaiya | C17: 45637 | D17: 2000 | E17: 500
A18: 16 | B18: Akhil Sir | C18: 45649 | D18: 2000 | E18: 500
A19: 17 | B19: Amit Sir | C19: 45649 | D19: 2000 | E19: 500
A20: 18 | B20: Ajeet Sir | C20: 45649 | D20: 2000 | E20: 500
A21: 19 | B21: Karan Singh | C21: 45649 | D21: 2000 | E21: 500
A22: 20 | B22: Imran Sir | C22: 45651 | D22: 2000 | E22: 500
A23: 21 | B23: Rishab Dube | C23: 45650 | D23: 2000 | E23: 0
A24: 22 | B24: Rahul Bhai | C24: 45653 | D24: 2000 | E24: 500
A25: 23 | B25: Ramiz (Sekhu) | C25: 45656 | D25: 2000 | E25: 500
A26: 24 | B26: Saud | D26: Exempt
A27: 25 | B27: Atik Ahmad | C27: 45671 | D27: 2000 | E27: 0
A28: 26 | B28: Shahabuddin Ahmad | C28: 45671 | D28: 2000 | E28: 0
A29: 27 | B29: Kaushal Sir | C29: 45661 | D29: 2000 | E29: 500
A30: 28 | B30: Gagan Prakash Sir | C30: 45709 | D30: 2000
A31: 29 | B31: Sagar Sir | C31: 45649 | D31: 2000 | E31: 500
A32: 30 | B32: Deepak sahni | C32: 45693 | D32: 2000 | E32: 0
A33: 31 | B33: Umar dujana | C33: 45694 | D33: 2000 | E33: 0
A34: 32 | B34: Mayank Verma | C34: 45666 | D34: 2000 | E34: 0
A35: 33 | B35: Santosh Maurya | C35: 45667 | D35: 2000 | E35: 0
D36: =SUM(D3:D35) -> 42000 | E36: =SUM(E3:E35) -> 11500
B39: Dec Collection | C39: =D36+E36 -> 53500
B40: Prev Balance | C40: =NOV!C22 -> -2020
B41: Total Collection Amount | C41: =D36+E36 -> 53500
B42: Total Expenses Amount | C42: =J15 -> 17450
...

Sheet 2025 Jan-Dec
A1: Team Budget Jan to Dec-2025 Collection
A2: Sr No. | B2: Member Name | C2: Jan | D2: Feb | E2: Mar | F2: Apr | G2: May | H2: Jun | I2: Jul | J2: Aug | K2: Sep | L2: Oct | M2: Nov | N2: Dec | O2: Equipements | P2: Track Suit
A3: 1 | B3: Aashit Srivastava | C3: No Member | D3: No Member | E3: No Member | F3: 750 | G3: 750 | H3: 750 | I3: 750 | J3: 750 | K3: 750 | L3: 750 | M3: 750 | N3: 750 | O3: 500 | P3: 500
A4: 2 | B4: Abhay Shukla | C4: No Member | D4: No Member | E4: No Member | F4: No Member | G4: No Member | H4: No Member | I4: No Member | J4: No Member | K4: No Member | L4: No Member | M4: 750 | N4: 750 | O4: No Member | P4: 500
A5: 3 | B5: Abhay Singh | C5: Absent | D5: 750 | E5: 750 | F5: 750 | G5: 750 | H5: 750 | I5: 750 | J5: 750 | K5: 750 | L5: 750 | M5: 750 | N5: 750 | O5: 500
A6: 4 | B6: Abhishek Pandey | C6: No Member | D6: No Member | E6: No Member | F6: No Member | G6: No Member | H6: No Member | I6: No Member | J6: No Member | K6: No Member | L6: No Member | M6: No Member | N6: 750 | O6: No Member | P6: Exempt
A7: 5 | B7: Abhishek Rai | C7: No Member | D7: No Member | E7: No Member | F7: 750 | G7: 750 | H7: 750 | I7: 750 | J7: 750 | K7: 750 | L7: 750 | M7: 750 | N7: 750 | O7: 500 | P7: 500
A8: 6 | B8: Ajeet Verma | C8: 750 | D8: 750 | E8: 750 | F8: 750 | G8: 750 | H8: 750 | I8: 750 | J8: 750 | K8: 750 | L8: 750 | M8: 750 | N8: 750 | O8: 500 | P8: 500
A9: 7 | B9: Akash Pandey | C9: No Member | D9: No Member | E9: No Member | F9: No Member | G9: 750 | H9: 750 | I9: 750 | J9: 750 | O9: No Member
A10: 8 | B10: Akhil Singh | C10: 750 | D10: 750 | E10: 750 | F10: 750 | G10: 750 | H10: 750 | I10: 750 | J10: 750 | K10: 750 | L10: 750 | M10: 750 | N10: 750 | O10: 500 | P10: 500
A11: 9 | B11: Amit Singh (Bade) | C11: 750 | D11: 750 | E11: 750 | F11: 500 | G11: 750 | H11: 750 | I11: 750 | J11: 750 | K11: 750 | L11: 750 | M11: 750 | N11: 750 | O11: 500 | P11: 500
A12: 10 | B12: Amit Singh (Chhotu) | C12: Absent | D12: Absent | E12: 750 | F12: 750 | G12: Absent | H12: Absent | I12: 750 | J12: 750 | K12: 750 | L12: 750 | O12: 450 | P12: 500
A13: 11 | B13: Amit Singh- Bhaiya | C13: 750 | D13: 750 | E13: 750 | F13: 750 | G13: 750 | H13: 4750 | I13: 750 | J13: 750 | K13: 750 | L13: 750 | M13: 750 | N13: 750 | O13: 500 | P13: 500
A14: 12 | B14: Apporv Patel | C14: No Member | D14: No Member | E14: No Member | F14: No Member | G14: No Member | H14: No Member | I14: No Member | J14: 750 | K14: 750 | L14: Absent | M14: 750 | O14: No Member
A15: 13 | B15: Ayush Mishra | C15: No Member | D15: No Member | E15: 500 | F15: 750 | G15: 750 | H15: 750 | I15: 750 | J15: 750 | K15: 750 | L15: 750 | M15: 250 | O15: No Member | P15: 500
A16: 14 | B16: Deepak Kanaujiya | C16: 750 | D16: 750 | E16: 750 | F16: 750 | G16: 750 | H16: 750 | I16: 750 | J16: 750 | K16: 750 | M16: Absent | N16: Absent | O16: 500 | P16: 1000
A17: 15 | B17: Deepak Sahni | C17: Absent | D17: 750 | E17: 750 | F17: 750 | O17: No Member
A18: 16 | B18: Dr Atul Yadav | C18: No Member | D18: No Member | E18: No Member | F18: No Member | G18: No Member | H18: No Member | I18: No Member | J18: No Member | K18: 750 | L18: 750 | M18: 750 | N18: 750 | O18: No Member | P18: 500
A19: 17 | B19: Dr Kalim | C19: No Member | D19: No Member | E19: No Member | F19: No Member | G19: 750 | H19: 750 | I19: 750 | J19: 750 | K19: Absent | L19: Absent | M19: 750 | N19: 750 | O19: 500 | P19: 500
A20: 18 | B20: Gaurav Tripathi | C20: 750 | D20: 750 | E20: 750 | F20: 750 | G20: 750 | H20: 750 | I20: 750 | J20: 750 | K20: 750 | L20: 750 | M20: 750 | N20: 750 | O20: 500 | P20: 500
A21: 19 | B21: Hassan | C21: 750 | D21: 750 | E21: 750 | F21: 750 | G21: 750 | H21: 750 | I21: 750 | J21: 750 | K21: 750 | L21: 750 | M21: 750 | N21: 750 | O21: 500 | P21: 500
A22: 20 | B22: Imran | C22: No Member | D22: No Member | E22: No Member | F22: No Member | G22: No Member | H22: No Member | I22: No Member | J22: No Member | K22: No Member | L22: No Member | M22: No Member | N22: 750 | O22: No Member | P22: Exempt
A23: 21 | B23: Karan Singh | C23: 750 | D23: 750 | E23: 750 | F23: 750 | G23: 750 | H23: 750 | I23: 750 | J23: 750 | K23: 750 | L23: 750 | M23: 750 | N23: 750 | O23: 500 | P23: 500
A24: 22 | B24: Kaushal Katiyar | C24: 750 | D24: 750 | E24: 750 | F24: 750 | G24: 750 | H24: 750 | I24: 750 | J24: 750 | K24: 750 | L24: 750 | M24: 750 | N24: 750 | O24: 500 | P24: 500
A25: 23 | B25: Madhusoodan Shukla | C25: 750 | D25: 750 | E25: 750 | F25: 750 | G25: 750 | H25: 750 | I25: 750 | J25: 750 | K25: 750 | L25: 750 | M25: 750 | N25: 750 | O25: 500 | P25: 500
A26: 24 | B26: Mahendra Yadav | C26: No Member | D26: No Member | E26: No Member | F26: No Member | G26: 750 | H26: 750 | I26: 750 | J26: 750 | K26: 750 | L26: 750 | M26: 750 | N26: 750 | O26: No Member | P26: 500
A27: 25 | B27: Rahul Verma | C27: 750 | D27: 750 | E27: 750 | F27: 750 | G27: 750 | H27: 750 | I27: 750 | J27: 750 | K27: 750 | L27: 750 | M27: 750 | N27: 750 | O27: 500 | P27: 500
A28: 26 | B28: Ramiz (Sekhu) | C28: 750 | D28: 750 | E28: 750 | F28: 750 | G28: 750 | H28: 750 | I28: 750 | J28: 750 | K28: 750 | L28: 750 | M28: 750 | N28: 750 | O28: 500 | P28: 500
A29: 27 | B29: Rishab Dubey | C29: 750 | D29: 750 | E29: 750 | F29: 750 | G29: 750 | H29: 750 | I29: 750 | J29: 750 | K29: 750 | L29: 750 | M29: 750 | N29: 750 | O29: 500 | P29: 500
A30: 28 | B30: Saud | C30: Exempt | D30: Exempt | E30: Exempt | F30: Exempt | G30: Exempt | H30: Exempt | I30: Exempt | J30: 750 | K30: Exempt | L30: Exempt | M30: Exempt | N30: Exempt | O30: Exempt | P30: 500
A31: 29 | B31: Saurabh Yadav | C31: No Member | D31: No Member | E31: No Member | F31: 750 | G31: No Member | H31: No Member | I31: No Member | J31: No Member | K31: No Member | L31: No Member | M31: No Member | N31: 750 | O31: No Member | P31: Exempt
A32: 30 | B32: Shalu | C32: 750 | D32: 750 | E32: 750 | F32: 750 | G32: 750 | H32: 750 | I32: 750 | J32: No Member | K32: 750 | L32: 750 | M32: 750 | N32: 900 | O32: 500 | P32: 500
A33: 31 | B33: Shivakant Mishra | C33: No Member | D33: No Member | E33: No Member | F33: No Member | G33: No Member | H33: No Member | I33: No Member | J33: 750 | K33: 750 | L33: 750 | M33: 750 | N33: 750 | O33: No Member | P33: 500
A34: 32 | B34: Shivam Singh | C34: 750 | D34: 750 | E34: 750 | F34: 750 | G34: 750 | H34: 750 | I34: 750 | J34: 750 | K34: 750 | L34: 750 | M34: 750 | N34: 750 | O34: 500 | P34: 500
A35: 33 | B35: Shubham Singh | C35: No Member | D35: No Member | E35: No Member | F35: No Member | G35: No Member | H35: No Member | I35: No Member | J35: No Member | K35: No Member | L35: No Member | M35: No Member | N35: No Member | O35: No Member | P35: 500
A36: 34 | B36: Sunil Kumar | C36: 750 | D36: 750 | E36: 750 | F36: 750 | G36: 750 | H36: 800 | I36: 750 | J36: 750 | K36: 750 | L36: 750 | M36: 750 | N36: 750 | O36: 500 | P36: 500
A37: 35 | B37: Vivek Pandey | C37: No Member | D37: No Member | E37: No Member | F37: 750 | G37: No Member | H37: No Member | I37: No Member | J37: No Member | K37: No Member | L37: No Member | M37: No Member | N37: 750 | O37: No Member | P37: Exempt
A38: 36 | B38: Zikrul | C38: 750 | D38: 750 | E38: 750 | F38: 750 | G38: 750 | H38: 750 | I38: 750 | J38: 750 | K38: 750 | L38: 750 | M38: 750 | N38: 750 | O38: 500 | P38: 500
A40: 7 | B40: Akash Maurya | C40: Absent | D40: Absent | E40: 750 | F40: 750 | G40: 750 | H40: Absent | I40: Absent | J40: 750 | K40: 750 | L40: Absent | M40: Absent | N40: Absent | O40: 500
A41: 15 | B41: Chitransh Ranjan | C41: No Member | D41: No Member | E41: No Member | F41: No Member | G41: No Member | H41: No Member | I41: No Member | J41: No Member | K41: No Member | L41: Absent | M41: Absent | N41: Absent | O41: No Member
...

Sheet 2026 Jan-Dec
A1: Team Budget Jan to Dec-2026 Collection
A2: Sr No. | B2: Member Name | C2: Jan | D2: Feb | E2: Mar | F2: Apr | G2: May | H2: Jun | I2: Jul | J2: Aug | K2: Sep | L2: Oct | M2: Nov | N2: Dec | O2: Equipements | P2: Track Suit
A3: 1 | B3: Aashit Srivastava | C3: 750 | D3: 1050
A4: 2 | B4: Abhay Shukla
A5: 3 | B5: Abhay Singh | C5: 750
A6: 4 | B6: Abhishek Pandey
A7: 5 | B7: Abhishek Rai | C7: 750 | D7: 1050
A8: 6 | B8: Ajeet Verma | C8: 750
A9: 7 | B9: Akash Pandey
A10: 8 | B10: Akhil Singh | C10: 750
A11: 9 | B11: Amit Singh (Bade) | C11: 750 | D11: 1050
A12: 10 | B12: Amit Singh (Chhotu)
A13: 11 | B13: Amit Singh- Bhaiya | C13: 750
A14: 12 | B14: Apporv Patel
A15: 13 | B15: Ayush Mishra
A16: 14 | B16: Deepak Kanaujiya
A17: 15 | B17: Deepak Sahni
A18: 16 | B18: Dr Atul Yadav | C18: 750 | D18: 1050
A19: 17 | B19: Dr Kalim | D19: 1050
A20: 18 | B20: Gaurav Tripathi | C20: 750 | D20: 1050
A21: 19 | B21: Hassan | C21: 750 | D21: 1050
A22: 20 | B22: Imran
A23: 21 | B23: Karan Singh | C23: 750
A24: 22 | B24: Kaushal Katiyar | C24: 750
A25: 23 | B25: Madhusoodan Shukla | C25: 750 | D25: 1050
A26: 24 | B26: Mahendra Yadav
A27: 25 | B27: Rahul Verma | D27: 1050
A28: 26 | B28: Ramiz (Sekhu) | C28: 750 | D28: 1050
A29: 27 | B29: Rishab Dubey
A30: 28 | B30: Saud
A31: 29 | B31: Saurabh Yadav
A32: 30 | B32: Shalu
A33: 31 | B33: Shivakant Mishra | D33: 1050
A34: 32 | B34: Shivam Singh | C34: 750
A35: 33 | B35: Shubham Singh | C35: 750
A36: 34 | B36: Sunil Kumar | C36: 750 | D36: 1050
A37: 35 | B37: Vivek Pandey
A38: 36 | B38: Zikrul | C38: 750 | D38: 1050
A39: 37 | B39: Gyanendra Dixit | D39: 1050
A40: 38 | B40: Ashish Singh | D40: 1050
...

Sheet Sheet1
A1: Members list
A2: Sr No. | B2: Member Name | C2: Phone Number
A3: 1 | B3: Aashit Srivastava | C3: 9690009945
A4: 2 | B4: Abhay Shukla | C4: 8181828027
A5: 3 | B5: Abhay Singh | C5: 7905168891
A6: 4 | B6: Abhishek Pandey | C6: 7897235775
A7: 5 | B7: Abhishek Rai | C7: 8299857692
A8: 6 | B8: Ajeet Verma | C8: 9918771755
A9: 7 | B9: Akash Pandey | C9: 9044287798
A10: 8 | B10: Akhil Singh | C10: 9260921900
A11: 9 | B11: Amit Singh (Bade) | C11: 9936649911
A12: 10 | B12: Amit Singh (Chhotu) | C12: 8604789100
A13: 11 | B13: Amit Singh- Bhaiya | C13: 9415180824
A14: 12 | B14: Apporv Patel | C14: 8423067262
... A21: 19 | B21: Hassan | C21: 8800342162
A22: 20 | B22: Imran
A23: 21 | B23: Karan Singh | C23: 7398855007
A24: 22 | B24: Kaushal Katiyar | C24: 9919192260
A25: 23 | B25: Madhusoodan Shukla | C25: 9335154865
A26: 24 | B26: Mahendra Yadav | C26: 7905623794
A27: 25 | B27: Rahul Verma | C27: 9454321925
A28: 26 | B28: Ramiz (Sekhu) | C28: 9999815448
A29: 27 | B29: Rishab Dubey | C29: 6394548224
A30: 28 | B30: Saud | C30: 9369990152
A31: 29 | B31: Saurabh Yadav | C31: 9899664919
A32: 30 | B32: Shalu | C32: 7007634961
A33: 31 | B33: Shivakant Mishra | C33: 7275050518
A34: 32 | B34: Shivam Singh | C34: 8400302089
... A38: 36 | B38: Zikrul | C38: 7065196383

Sheet Tracksuit
A1: Total | C1: 32
A2: Tracksuit | J2: Extra | K2: Team | L2: Family | M2: Others
A3: S-36 | B3: M-38 | C3: L-40 | D3: XL-42 | E3: XXL-44 | H3: Tracksuit Size | I3: Number
A4: Apporv | B4: Saud | C4: Abhay Shukla | D4: Abhishek Rai | E4: Akhil | H4: S-36 | I4: =J4+K4+L4+M4 -> 2 | K4: 1 | M4: 1 | N4: Sandeep
B5: Amit Chhotu | C5: Karan | D5: Dr Kalim | E5: Madhu | H5: M-38 | I5: =J5+K5+L5+M5 -> 6 | J5: 2 | K5: 3 | M5: 1 | N5: Abhay Singh
B6: Sunil | C6: Ayush | D6: Amit Bhaiya | H6: L-40 | I6: =J6+K6+L6+M6 -> 27 | J6: 6 | K6: 18 | L6: 2 | M6: 1 | N6: Akash Pandey
C7: Shivam | D7: Gaurav | H7: XL-42 | I7: =J7+K7+L7+M7 -> 12 | J7: 2 | K7: 8 | M7: 2 | N7: Sagar | O7: Vijay
C8: Ramiz | D8: Aashit | H8: XXL-44 | I8: =J8+K8+L8+M8 -> 3 | K8: 2 | L8: 1
C9: Shalu | D9: Saurabh | I9: =SUM(I4:I8) -> 50 | J9: =SUM(J4:J8) -> 10 | K9: =SUM(K4:K8) -> 32 | L9: =SUM(L4:L8) -> 3 | M9: =SUM(M4:M8) -> 5
C10: Kaushak | D10: Deepak Kanaujia
C11: Mahendra | D11: Sahil | L11: Rashmi
C12: Rishab | D12: Imran | L12: Sparsh
C13: Shiva | L13: Shashwat
C14: Ajeet Verma
C15: Rahul | H15: Tracksuit Size | I15: S-36 | J15: M-38 | K15: L-40 | L15: XL-42 | M15: XXL-44 | N15: Total
C16: Hasan | H16: Total Extra | I16: 1 | J16: 4 | K16: 8 | L16: 3 | M16: 1 | N16: =SUM(I16:M16) -> 17
C17: Dr Atul | H17: Remaining | I17: 0 | J17: 2 | K17: 1 | L17: 3 | M17: 0 | N17: =SUM(I17:M17) -> 6
C18: Deepak Sahani | I18: Sandeep | J18: Shashwat | K18: Shailendra | M18: Sparsh
C19: Zikrul | J19: Pramood | K19: Vijay
C20: Abhishek | K20: Amit Bade
C21: Vivek | K21: Shubham
C22: Akash | K22: Akash
A23: 1 | B23: 3 | C23: 19 | D23: 9 | E23: 2 | K23: Abhay
K24: Amit Bade
A25: Team KK - Track Suite List
A26: S.No. | B26: Player Name | C26: Lower- Size | D26: Number on T-Shirt
A27: 1 | B27: Amit Singh Sir | C27: XL | D27: 1
A28: 2 | B28: Shiva | C28: L | D28: 02
A29: 3 | B29: Apporv Patel | C29: S | D29: 65
A30: 4 | B30: Abhishek Pandey | C30: L | D30: 05
A31: 5 | B31: Saurabh Yadav | C31: XL | D31: 06
A32: 6 | B32: Akhil Singh Sir | C32: XXL | D32: 07
A33: 7 | B33: Ayush | C33: L | D33: 08
A34: 8 | B34: Abhay Shukla | C34: L | D34: 09
A35: 9 | B35: Shivam Singh | C35: L | D35: 10
A36: 10 | B36: Madhu Soodan Shukla | C36: XXL | D36: 11
A37: 11 | B37: Vivek Pandey | C37: L | D37: 12
A38: 12 | B38: Deepak Kanaujiya | C38: XL | D38: 15
A39: 13 | B39: Sahil | C39: XL | D39: 15
A40: 14 | B40: Dr. Atul | C40: L | D40: 16
...

Sheet Pending
C1: Member Name | D1: Month | E1: Monthly Fee Remaining | F1: Tournament Fee | G1: Tracksuit | H1: Total Remaining | L1: KK11 | N1: SS Warriors
C2: Akash Pandey | D2: Sep-Jan | E2: 3750 | F2: 750 | G2: 500 | H2: =SUM(E2:G2) -> 5000 | L2: Team for Match at Scorpian Club Time - 07:30 A:M | N2: Team for Match at Scorpian Club Time - 02:00 P:M
C3: Abhay Shukla | D3: Jan | E3: 750 | F3: 0 | G3: 0 | H3: =SUM(E3:G3) -> 750 | L3: Dress: White | N3: Dress : Colour (orange)
C4: Deepak Kanaujiya | D4: Oct | E4: 750 | F4: 0 | G4: 0 | H4: =SUM(E4:G4) -> 750 | L4: Sr No | M4: Team Player | N4: Sr No | O4: Team Player
C5: Amit Singh (Chhotu) | D5: Nov-Jan | E5: 2250 | F5: 0 | G5: 0 | H5: =SUM(E5:G5) -> 2250 | L5: 1 | M5: Amit Singh | N5: 1 | O5: Zikrul
C6: Apporv Patel | D6: Dec-Jan | E6: 1500 | F6: 0 | G6: 500 | H6: =SUM(E6:G6) -> 2000 | L6: 2 | M6: Ajeet Verma | N6: 2 | O6: Kaushal Katiyar (C)
C7: Ayush Mishra | D7: Nov-Jan | E7: 2000 | F7: 0 | G7: 0 | H7: =SUM(E7:G7) -> 2000 | L7: 11 | M7: Madhosudan | N7: 11 | O7: Sunil
C8: Mahendra | D8: Jan | E8: 750 | F8: 500 | G8: 0 | H8: =SUM(E8:G8) -> 1250 | L8: 12 | M8: Rahul | N8: 12 | O8: Amit Bhaiya
C9: Rishab | D9: Jan | E9: 750 | F9: 0 | G9: 0 | H9: =SUM(E9:G9) -> 750
C10: Shivam | D10: - | E10: 0 | F10: 1000 | G10: 0 | H10: =SUM(E10:G10) -> 1000
C11: Deepak Sahani | D11: - | E11: 0 | F11: 0 | G11: 500 | H11: =SUM(E11:G11) -> 500
C12: Dr Atul | D12: - | E12: 0 | F12: 250 | G12: 0 | H12: =SUM(E12:G12) -> 250
C13: Kaushal Katiyar | D13: - | E13: 0 | F13: 250 | G13: 0 | H13: =SUM(E13:G13) -> 250
C14: Shalu | D14: Jan | E14: 600 | F14: 0 | G14: 0 | H14: =SUM(E14:G14) -> 600
C23: Total | E23: =SUM(E2:E14) -> 13100 | F23: =SUM(F2:F14) -> 2750 | G23: =SUM(G2:G14) -> 1500 | H23: =SUM(H2:H14) -> 17350
L24: 13 | M24: Shivakant | N24: 13 | O24: Gaurav
C27: Aashit Srivastava
C28: Abhishek Pandey
C29: Abishek Rai | D29: 750
C30: Ajeet Verma | D30: 750
C31: Akash Pandey
C32: Akhil Singh | D32: 750
C33: Amit Singh (Bade) | D33: 500
C34: Amit Singh (Chhotu)
C35: Amit Singh- Bhaiya | D35: 750
C36: Apporv Patel
C37: Ayush Mishra
C38: Deepak Kanaujiya
C39: Deepak Sahni
C40: Dr Atul Yadav | D40: 750
C41: Dr Kalim
C42: Gaura v Tripathi | D42: 750
C43: Hassan | D43: 750
C44: Imran
C45: Karan Singh | D45: 750
C46: Kaushal Katiyar | D46: 750
C47: Madhusoodan Shukla | D47: 750
C48: Rahul Verma
C49: Ramiz (Sekhu) | D49: 750
C50: Saurabh Yadav
...

Sheet Tournament
A2: Match Date | L2: Friendship Torunament Season 1
A3: Sr No | B3: Players | C3: 45714 | D3: 45725 | E3: 45732 | F3: 45739 | G3: 45753 | H3: Extra Paid | L3: Sr No | M3: Players | N3: 45921 | O3: 45927 | P3: 45977 | Q3: 45983 | R3: 45990 | S3: 45991
A4: 1 | B4: Amit Singh | C4: 400 | D4: 400 | E4: 400 | F4: 400 | G4: 400 | H4: 4400 | L4: 1 | M4: Aashit Srivastava | N4: 250 | O4: 250 | P4: No | Q4: No | S4: No
A5: 2 | B5: Ajeet Verma | C5: 400 | D5: 400 | E5: 400 | F5: 400 | G5: 400 | H5: 0 | L5: 2 | M5: Akash Pandey | N5: No | O5: Yes | P5: Yes | Q5: Yes | R5: No | S5: No
A6: 3 | B6: Akhil Singh | C6: 400 | D6: 400 | E6: 400 | F6: 400 | G6: 400 | L6: 3 | M6: Akhil Singh | N6: 250 | O6: 250 | P6: 250 | Q6: No | R6: No | S6: No
A7: 4 | B7: Shalu (C) | C7: 400 | D7: 400 | E7: 400 | F7: 400 | J7: Tournament Fee | K7: Amount (Rs) | L7: 4 | M7: Amit Singh- Bhaiya | N7: 250 | O7: 250 | P7: 250 | Q7: 250 | R7: 250 | S7: 250
A8: 5 | B8: Shivam Singh | C8: 400 | J8: Shalu | K8: 400 | L8: 5 | M8: Ayush Mishra | N8: 250 | O8: 250 | P8: No | Q8: No | R8: No | S8: No
A9: 6 | B9: Rahul Verma | C9: 400 | D9: 400 | E9: 400 | F9: 400 | G9: 400 | J9: Dr Vishal Pratap Singh | K9: 400 | L9: 6 | M9: Dr Atul Yadav | N9: No | O9: No | P9: 250 | Q9: 250 | R9: 250 | S9: No | U9: Team KK 11
A10: 7 | B10: Ujjwal | C10: 400 | D10: 400 | J10: Ujjwal | K10: 800 | L10: 7 | M10: Deepak Sahni | N10: Yes | O10: Yes | P10: Yes | Q10: Yes | R10: Yes | S10: Yes | U10: 1 | V10: Aashit Srivastava
A11: 8 | B11: Dr Vishal Pratap Singh | C11: 400 | J11: Satyendra | K11: 400 | L11: 8 | M11: Karan Singh | N11: 250 | O11: 250 | P11: 250 | Q11: No | R11: 250 | S11: 250 | U11: 2 | V11: Akash Pandey
A12: 9 | B12: Satyendra | C12: 400 | D12: 400 | E12: 400 | F12: 400 | L12: 9 | M12: Kaushal Katiyar | N12: 250 | O12: No | P12: No | Q12: No | R12: 250 | S12: No | U12: 3 | V12: Akhil Singh
A13: 10 | B13: Nikhil | C13: 400 | L13: 10 | M13: Madhusoodan Shukla | N13: No | O13: No | P13: No | Q13: No | R13: No | S13: No | U13: 4 | V13: Amit Singh
A14: 11 | B14: Mihir | E14: By Mgmt | F14: By Mgmt | G14: By Mgmt | L14: 11 | M14: Mahendra Yadav | N14: Yes | O14: Yes | P14: No | Q14: No | R14: No | S14: No | U14: 5 | V14: Ayush Mishra
A15: 12 | B15: Karan | L15: 12 | M15: Rahul Verma | N15: No | O15: 250 | P15: No | Q15: 250 | R15: 250 | S15: 250 | U15: 6 | V15: Dr Atul Yadav
A16: 13 | B16: Gaurav Tripathi | L16: 13 | M16: Rishab Dubey | N16: No | O16: 250 | P16: 250 | Q16: No | R16: 250 | S16: 250 | U16: 7 | V16: Gaurav Tripathi
A17: 14 | B17: Madhoosudan Shukla | L17: 14 | M17: Shalu | N17: 250 | O17: 250 | P17: 250 | Q17: 250 | R17: 250 | S17: 250 | U17: 8 | V17: Karan Singh
A18: 15 | B18: Sunil OCOC | D18: 400 | L18: 15 | M18: Shivam Singh | N18: 250 | O18: 250 | P18: 240 | Q18: 250 | R18: 250 | S18: 250 | U18: 9 | V18: Kaushal Katiyar
A19: 16 | B19: Rishab Dubey | C19: By Mgmt | L19: 16 | M19: Sunil Kumar | N19: 250 | O19: 250 | P19: 250 | Q19: 250 | R19: 250 | S19: 250 | U19: 10 | V19: Madhusoodan Shukla
A20: 17 | B20: Ayush | D20: By Mgmt | L20: 17 | M20: Zikrul | N20: No | O20: 250 | P20: 250 | Q20: 250 | R20: 250 | S20: No | U20: 11 | V20: Mahendra Yadav
A21: 18 | B21: Pradeep | D21: By Mgmt | E21: By Mgmt | F21: By Mgmt | G21: By Mgmt | L21: 18 | M21: Ajeet Verma | N21: 250 | O21: 250 | P21: 250 | Q21: 250 | R21: 250 | S21: 250 | U21: 12 | V21: Rahul Verma
A22: 19 | B22: Ankur Sain | D22: 400 | F22: 400 | L22: 19 | M22: Amit Singh (Chhotu) | N22: No | O22: No | P22: No | Q22: No | R22: No | S22: No | U22: 13 | V22: Rishab Dubey
A23: 20 | B23: Monty | E23: 400 | F23: 400 | L23: Total Players | N23: =SUM(N6:N22) -> 2250 | O23: =SUM(O6:O22) -> 2750 | P23: =SUM(P6:P22) -> 2490 | Q23: =SUM(Q6:Q22) -> 2000 | R23: =SUM(R6:R22) -> 2750 | S23: =SUM(S6:S22) -> 2000 | U23: 14 | V23: Shalu
A24: Total | C24: =SUM(C4:C23) -> 4000 | D24: =SUM(D4:D23) -> 3600 | E24: =SUM(E4:E23) -> 2800 | F24: =SUM(F4:F23) -> 3200 | G24: =SUM(G4:G23) -> 1600 | H24: =SUM(H4:H23) -> 4400 | L24: 20 | M24: Abhay Singh | U24: 15 | V24: Shivam Singh
L25: 21 | M25: Abishek Rai | U25: 16 | V25: Sunil Kumar
L26: 22 | M26: Akash Maurya | U26: 17 | V26: Zikrul
B27: Extra Payment by Players | C27: =H24 -> 4400 | L27: 23 | M27: Amit Singh (Bade) | U27: 18 | V27: Ajeet Verma
B28: Payment By Players | C28: =C24+D24+E24+F24+G24 -> 15200 | L28: 24 | M28: Apporv Patel | U28: 19 | V28: Amit Singh
B29: Extra Payment by Mgmt | C29: 2800 | G29: Total Expenditure | H29: =SUM(H31:H39) -> 21850 | L29: 25 | M29: Deepak Kanaujiya
B30: Total Collection Amount | C30: =C28+C29 -> 18000 | F30: Payment Details | L30: 26 | M30: Gaurav
B31: Total Expenses Amount | C31: =H29 -> 21850 | F31: 1 | G31: Tournament fee | H31: 10500 | L31: 27 | M31: Dr Kalim
B32: Balance Amount | C32: =C30-C31 -> -3850 | F32: 2 | G32: Tournament fee | H32: 10500 | L32: 28 | M32: Hassan
F33: 3 | G33: Lunch | H33: 850 | L33: 29 | M33: Ramiz (Sekhu)
L34: 30 | M34: Sagar Mehra
L35: 31 | M35: Saud
L36: 32 | M36: Shivakant
L37: 33 | M37: Umar Dujana
K46: 240

Sheet Extra Match
A1: Extra Match
A2: Serial No. | B2: Member Name | C2: 45710 | D2: 45718 | E2: 45843 | F2: 45845 | G2: 45848
A3: 1 | B3: Akhil Singh | C3: 350 | D3: 300 | E3: 500 | F3: 250 | G3: 500
A4: 2 | B4: Zikrul | C4: 350 | D4: NP | E4: 500 | F4: 250 | G4: 500
A5: 3 | B5: Shalu | C5: 350 | D5: 300 | E5: 500 | F5: 250 | G5: 500
A6: 4 | B6: Shivam | C6: 350 | D6: 300 | E6: NP | F6: NP | G6: 500
A7: 5 | B7: Ajeet Kumar Verma | C7: 350 | D7: 300 | E7: 500 | F7: 250 | G7: 500
A8: 6 | B8: Amit Singh Bhaiya | C8: 350 | D8: 300 | E8: 500 | F8: 250 | G8: 500
A9: 7 | B9: Sunil Kumar OCOP | C9: 350 | D9: 300 | E9: NP | F9: 250 | G9: 500
A10: 8 | B10: Rishab | C10: 350 | D10: NP | E10: 500 | F10: NP | G10: NP
A11: 9 | B11: Karan | C11: 350 | D11: 300 | E11: 500 | F11: 250 | G11: 500
A12: 10 | B12: Ayush | C12: 350 | D12: By Mgmt
A13: 11 | B13: Sujal Gwasikoti | C13: 350 | D13: NP
A14: 12 | B14: Pradeep | C14: NP | D14: By Mgmt
A15: 13 | B15: Akash Pandey | C15: NP | D15: NP | E15: 500 | F15: 250
A16: 14 | B16: Nishant | C16: NP | D16: NP | E16: NP | F16: NP | G16: NP
A17: 15 | B17: Aashit Srivastava | C17: NP | D17: NP | E17: NP | F17: NP | G17: NP
A18: 16 | B18: Hasan | C18: 350 | D18: NP | E18: NP | F18: NP | G18: NP
A19: 17 | B19: Kaushal | C19: 350 | D19: NP | E19: NP | F19: NP | G19: NP
A20: 18 | B20: Vishal(Deepak Kanaujiya) | C20: 350 | D20: NP | E20: NP | F20: NP | G20: NP
A21: 19 | B21: Deepak sahani | C21: 350 | D21: NP | E21: NP | F21: NP | G21: NP
A22: 20 | B22: Abhay Singh | C22: 350 | D22: NP | E22: NP | F22: NP | G22: NP
A23: 21 | B23: Sagar | C23: 350 | D23: NP | E23: NP | F23: NP | G23: NP
A24: 22 | B24: Umar Dujana | C24: 350 | D24: NP | E24: NP | F24: NP | G24: NP
A25: 23 | B25: Madhusoodan | C25: 350 | D25: 300 | E25: NP | F25: NP | G25: NP
A26: 24 | B26: Ramiz Raza | C26: 350 | D26: NP | E26: NP | F26: NP | G26: NP
A27: 25 | B27: Gaurav Tripathi | C27: 350 | D27: 300 | E27: NP | F27: NP | G27: NP
A28: 26 | B28: Deepak Kanaujiy | C28: 350 | D28: NP | E28: NP | F28: NP | G28: NP
A29: 27 | B29: Abhay Singh | C29: 350 | D29: NP | E29: NP | F29: NP | G29: NP
A30: 28 | B30: Amit Singh DULB | C30: 350 | D30: NP | E30: NP | F30: NP | G30: NP
A37: Total | C37: =SUM(C3:C36) -> 8400 | D37: =SUM(D3:D36) -> 2700 | E37: =SUM(E3:E36) -> 4000 | F37: =SUM(F3:F36) -> 2000 | G37: =SUM(G3:G36) -> 4000 | H37: =SUM(H3:H36) -> 0 | I37: =SUM(I3:I36) -> 0 | J37: =SUM(J3:J36) -> 0 | ... W37: =SUM(W3:W36) -> 0
F40: Total Expenditure | G40: =SUM(G42:G189) -> 10800 | I40: NP = | J40: Not Played
B41: Extra Payment by Mgmt | C41: 0 | E41: Payment Details
B42: Total Collection Amount | C42: =C37+D37+E37+F37+G37+H37+I37+J37+K37+L37+M37+N37+O37+P37+Q37+R37+S37+T37+U37+V37+W37+C41 -> 21100 | E42: 1 | F42: Sage Ground | G42: 7500
B43: Total Expenses Amount | C43: =G40 -> 10800 | E43: 2 | F43: DGI Ground | G43: 3300
B44: Balance Amount | C44: =C42-C43 -> 10300

Sheet Teams
A1: Team KK11 | C1: SS-Warriors | G1: SS | I1: Sr No | J1: Team DLB | K1: Team NV Fighter
A2: 1 | B2: Akash Pandey | C2: 1 | D2: Hasan Raza | I2: 1 | J2: Abhay Singh | K2: Aashit Srivastava
A3: 2 | B3: Amit Singh- Bhaiya | C3: 2 | D3: Shivam Singh | I3: 2 | J3: Abishek Rai | K3: Ajeet Verma(C)
A4: 3 | B4: Aashit Srivastava | C4: 3 | D4: Sunil Kumar OCOP | I4: 3 | J4: Akhil Singh (C) | K4: Akash Pandey
A5: 4 | B5: Rahul Verma (Wk) | C5: 4 | D5: Deepak Kanaujiya (Wk) | I5: 4 | J5: Amit Singh (Bade) | K5: Amit Singh- Bhaiya
A6: 5 | B6: Ajeet Verma | C6: 5 | D6: Ramiz Raza | I6: 5 | J6: Deepak Kanaujiya | K6: Apporv Patel
A7: 6 | B7: Akhil Singh (C) | C7: 6 | D7: Zikrul (C) | I7: 6 | J7: Gaurav Tripathi | K7: Ayush Mishra
A8: 7 | B8: Rishab Dubey | C8: 7 | D8: Karan Singh | I8: 7 | J8: Hassan | K8: Deepak Sahni
A9: 8 | B9: Kaushal Katiyar | C9: 8 | D9: Mahendra Yadav | I9: 8 | J9: Karan Singh | K9: Dr Kalim
A10: 9 | B10: Sagar Mehra | C10: 9 | D10: Saudur | I10: 9 | J10: Madhusoodan Shukla | K10: Kaushal Katiyar
A11: 10 | B11: Gaurav Tripathi | C11: 10 | D11: Abhishek Rai | I11: 10 | J11: Mahendra Yadav | K11: Mayank Verma
A12: 11 | B12: Apoorv Patel | C12: 11 | D12: Amit Singh (Bade) | I12: 11 | J12: Rahul Verma | K12: Ramiz (Sekhu)
A13: 12 | B13: Mayank Verma | C13: 12 | D13: Abhay Singh | I13: 12 | J13: Rishab Dubey | K13: Sagar Mehra
... A15: 14 | B15: Shivakant | C15: 14 | D15: Saurabh Tripathi | I15: 14 | J15: Shivam Singh | K15: Saurabha Tripathi
I16: 15 | J16: Sunil Kumar OCOP | K16: Umar Dujana
I17: 16 | J17: Zikrul
A21: Team KK11 | C21: SS-Warriors | I21: 13 सितम्बर को स्थानीय निकाय निदेशालय एवं शासन के मध्य सेज क्रिकेट मैदान में एक रात्रि क्रिकेट मैच आयोजित किया जा रहा है , जिसके द्रष्टिगत दिनांक 30 अगस्त, 02, 06 एवं 09 सितम्बर को KK क्रिकेट क्लब की 2 टीम (Team DLB एवं Team NV Fighters) के मध्य Club के द्वारा सेज मैदान में मैच आयोजित किया जा रहा है , जिसका विवरण निम्नवत है (इन मैच का कोई भी अतिरिक्त शुल्क टीम सदस्यों द्वारा नहीं लिया जायेगा ):-
A22: 1 | B22: Aashit Srivastava | C22: 1 | D22: Deepak Kanaujiya
A23: 2 | B23: Amit Singh- Bhaiya | C23: 2 | D23: Shalu
A24: 3 | B24: Rishab Dubey | C24: 3 | D24: Deepak Sahni
A25: 4 | B25: Ajeet Verma | C25: 4 | D25: Ramiz | I25: क्रम स0 | J25: दिनांक | K25: पाली | L25: ड्रेस ( टीम DLB) | M25: ड्रेस ( टीम NV फाइटर)
A26: 5 | B26: Akhil Singh(C) | C26: 5 | D26: Amit Singh (Bade) | I26: 1 | J26: 30 अगस्त | K26: 2nd (प्रातः 11 से 03 ) | L26: New Blue | M26: Orange
A27: 6 | B27: Kaushal Katiyar | C27: 6 | D27: Sunil Kumar | I27: 2 | J27: 02 सितम्बर | K27: रात्रि (सांय 07 से 11) | L27: Orange | M27: New Blue
A28: 7 | B28: Dr Atul Yadav | C28: 7 | D28: Karan Singh | I28: 3 | J28: 06 सितम्बर | K28: 1st (प्रातः 06 से 10 ) | L28: New Blue | M28: Orange
A29: 8 | B29: Saud | C29: 8 | D29: Akash Maurya | I29: 4 | J29: 09 सितम्बर | K29: रात्रि (सांय 07 से 11) | L29: Orange | M29: New Blue
A30: 9 | B30: Akash Pandey | C30: 9 | D30: Zikrul
A31: 10 | B31: Ayush Mishra | C31: 10 | D31: Shivam Singh | I31: Sr No | J31: Team DLB | L31: Team NV Fighter
A32: 11 | B32: Mahendra Yadav | C32: 11 | D32: Apporv Patel | I32: 1 | J32: Abhay Singh | L32: Aashit Srivastava
A33: 12 | B33: Madhusoodan Shukla | C33: 12 | D33: Hassan | I33: 2 | J33: Abishek Rai | L33: Ajeet Verma(C)
A34: 13 | B34: Gaurav Tripathi | C34: 13 | D34: Dr Kalim | I34: 3 | J34: Akhil Singh (C) | L34: Akash Pandey
A35: 14 | B35: Abishek Rai | C35: 14 | D35: Umar Dujana | I35: 4 | J35: Amit Singh (Bade) | L35: Amit Singh- Bhaiya
A36: 15 | B36: Sagar Mehra | C36: 15 | D36: Abhay Singh | I36: 5 | J36: Deepak Kanaujiya | L36: Apporv Patel
A37: 16 | B37: Shivakant | C37: 16 | D37: Amit Singh (Chhotu) | I37: 6 | J37: Gaurav Tripathi | L37: Ayush Mishra
A38: 17 | B38: Rahul Verma | I38: 7 | J38: Hassan | L38: Deepak Sahni
I39: 8 | J39: Zikrul | L39: Dr Kalim
I40: 9 | J40: Madhusoodan Shukla | L40: Kaushal Katiyar
I41: 10 | J41: Mahendra Yadav | L41: Mayank Verma
I42: 11 | J42: Rahul Verma | L42: Ramiz (Sekhu)
I43: 12 | J43: Rishab Dubey | L43: Sagar Mehra
I44: 13 | J44: Shivakant | L44: Saudur
...

Sheet Inventary
A1: KK-11 Cricket Inventory
A2: Serial No. | B2: Category | C2: Items | D2: Quantity | E2: Available | F2: Missing | G2: Destroy | H2: Distributed
A3: 1 | B3: Ad and Supporters | C3: Pair AD and Supporters | D3: 6 | H3: 6
C4: Pair AD and Supporters | D4: 5 | H4: 1
A5: 2 | B5: Bag | C5: Kit Bag (NS-2, Shrey-1, SS-1) | D5: 4 | E5: 4
A6: 3 | B6: Bat | C6: SS Bat Kashmiri Willow | D6: 2 | E6: 1
C7: SS TON Bat Kashmiri Willow | D7: 1 | E7: 1
C8: Gray Nicolls Bat Kashmiri Willow | D8: 1 | E8: 0 | G8: 1
C9: CG Bat | D9: 2 | E9: 2
A10: 4 | B10: Elbow | C10: SG Test Elbow Guard | D10: 2 | E10: 2
A11: 5 | B11: Gloves | C11: SS Superlite Batting Gloves (Youth) | D11: 2
C12: SS Platino Batting Gloves (Youth) | D12: 2
C13: Gray Nicolls Pro Edition Gloves (Adult) | D13: 1
C14: SS Gloves - CS | D14: 1
C15: AP Power 4.0 | D15: 1
C16: AP Test Pro | D16: 1
C17: AP Genius Le | D17: 2
A18: 6 | B18: Helmet | C18: DSC Helmet | D18: 3
C19: Shrey Helmet | D19: 1
A20: 7 | B20: Keeping Gloves | C20: SS Wicket Keeping Gloves | D20: 1
C21: SG Wicket Keeping Gloves | D21: 1
C22: V Pro Keeping Gloves | D22: 1
C23: SS Wicket Keeping Gloves -Super | D23: 1
A24: 8 | B24: Keeping Inner Gloves | C24: Gray Nicolls Wicket Keeping Inner Gloves | D24: 1
C25: SG Wicket Keeping Inner Gloves | D25: 1
C26: SS Wicket Keeping Inner Gloves | D26: 3
A27: 9 | B27: Keeping Leg Guard | C27: Moonwalkr Wicket Keeping Leg Guard | D27: 1
C28: SS Players Edition | D28: 1
A29: 10 | B29: Leg Guard | C29: SS Platino Leg Guard (Boys) | D29: 1
C30: SS Platino Leg Guard (Youth) | D30: 1
C31: AJ Leg Guard (Youth) | D31: 1
C32: AJ Leg Guard (Mens) | D32: 1
C33: CS Adult | D33: 1
A34: 11 | B34: Rapid Arm | C34: Rapid Arm | D34: 1
A35: 12 | B35: Stumps | C35: NS Stumps | D35: 7
C36: AJ Stumps with Bails | D36: 9
A37: 13 | B37: Thigh | C37: SG Ultimate Thigh Guard | D37: 2
C38: Moonwalkr Thigh Guard (Small) | D38: 1
C39: Moonwalkr Thigh Guard (Medium) | D39: 1
A43: Total | D43: =SUM(D3:D42) -> 74 | E43: =SUM(E3:E42) -> 10 | F43: =SUM(F3:F42) -> 0 | G43: =SUM(G3:G42) -> 1 | H43: =SUM(H3:H42) -> 7
